<!-- DH Parameters and constraints
      Name     theta         d         a     alpha    effort     lower     upper  velocity    visual
  revolute       0.0       3.0       3.0       0.0        10   -3.1416    3.1416       2.6         1
  revolute       0.0       0.0       3.0   -3.1416        10   -2.0944    2.0944       2.6         1
 prismatic       0.0       0.0       0.0       0.0        10       0.8         3       2.6         1
  revolute       0.0       0.0       0.0       0.0        10   -3.1416    3.1416       2.6         1
-->
<robot name='robot'>
	<material name='grey'>
		<color rgba='0.6 0.6 0.6 1'/>
	</material>
	<material name='white'>
		<color rgba='1 1 1 1'/>
	</material>
	<link name='a0'>
		<visual>
			<origin rpy='0 0 0' xyz='0 0 0'/>
			<geometry>
				<cylinder length='0.7' radius='0.43'/>
			</geometry>
			<material name='grey'/>
		</visual>
	</link>
	<link name='l0'>
		<visual>
			<origin rpy='-0.0 0.7853981633974483 0.0' xyz='1.5 0.0 1.5'/>
			<geometry>
				<cylinder length='4.242640687119285' radius='0.3'/>
			</geometry>
			<material name='white'/>
		</visual>
	</link>
	<joint name='move_l0_from_a0' type='revolute'>
		<parent link='a0'/>
		<child link='l0'/>
		<axis xyz='0 0 1'/>
		<origin rpy='0 0 0' xyz='0 0 0'/>
		<limit effort='10' lower='-3.141592653589793' upper='3.141592653589793' velocity='2.6'/>
	</joint>
	<link name='a1'>
		<visual>
			<origin rpy='0 0 0' xyz='3.00000000000000 0 3.00000000000000'/>
			<geometry>
				<cylinder length='0.7' radius='0.43'/>
			</geometry>
			<material name='grey'/>
		</visual>
	</link>
	<joint name='fix_a1_to_l0' type='fixed'>
		<parent link='l0'/>
		<child link='a1'/>
		<axis xyz='0 0 1'/>
		<origin rpy='0 0 0' xyz='0 0 0'/>
	</joint>
	<link name='l1'>
		<visual>
			<origin rpy='-0.0 1.5707963267948966 0.0' xyz='1.5 0.0 0.0'/>
			<geometry>
				<cylinder length='3.0' radius='0.3'/>
			</geometry>
			<material name='white'/>
		</visual>
	</link>
	<joint name='move_l1_from_a1' type='revolute'>
		<parent link='a1'/>
		<child link='l1'/>
		<axis xyz='0 0 1'/>
		<origin rpy='0 0 0' xyz='3.00000000000000 0 3.00000000000000'/>
		<limit effort='10' lower='-2.0943951023931953' upper='2.0943951023931953' velocity='2.6'/>
	</joint>
	<link name='a2'>
		<visual>
			<origin rpy='-3.14159265358979 0 0' xyz='3.00000000000000 0 0'/>
			<geometry>
				<cylinder length='0.7' radius='0.43'/>
			</geometry>
			<material name='grey'/>
		</visual>
	</link>
	<joint name='fix_a2_to_l1' type='fixed'>
		<parent link='l1'/>
		<child link='a2'/>
		<axis xyz='0 0 1'/>
		<origin rpy='0 0 0' xyz='0 0 0'/>
	</joint>
	<link name='l2'>
		<visual>
			<origin rpy='0 0 0' xyz='0.0 0.0 0.0'/>
			<geometry>
				<cylinder length='0.0' radius='0.3'/>
			</geometry>
			<material name='white'/>
		</visual>
		<visual>
			<origin rpy='0 0 0' xyz='0 0 -1.225'/>
			<geometry>
				<cylinder length='3' radius='0.3'/>
			</geometry>
			<material name='white'/>
		</visual>
	</link>
	<joint name='move_l2_from_a2' type='prismatic'>
		<parent link='a2'/>
		<child link='l2'/>
		<axis xyz='0 0 1'/>
		<origin rpy='-3.14159265358979 0 0' xyz='3.00000000000000 0 0'/>
		<limit effort='10' lower='0.8' upper='3' velocity='2.6'/>
	</joint>
	<link name='a3'>
		<visual>
			<origin rpy='0 0 0' xyz='0 0 0'/>
			<geometry>
				<cylinder length='0.7' radius='0.43'/>
			</geometry>
			<material name='grey'/>
		</visual>
	</link>
	<joint name='fix_a3_to_l2' type='fixed'>
		<parent link='l2'/>
		<child link='a3'/>
		<axis xyz='0 0 1'/>
		<origin rpy='0 0 0' xyz='0 0 0'/>
	</joint>
	<link name='l3'>
		<visual>
			<origin rpy='0 0 0' xyz='0.0 0.0 0.0'/>
			<geometry>
				<cylinder length='0.0' radius='0.3'/>
			</geometry>
			<material name='white'/>
		</visual>
	</link>
	<joint name='move_l3_from_a3' type='revolute'>
		<parent link='a3'/>
		<child link='l3'/>
		<axis xyz='0 0 1'/>
		<origin rpy='0 0 0' xyz='0 0 0'/>
		<limit effort='10' lower='-3.141592653589793' upper='3.141592653589793' velocity='2.6'/>
	</joint>
	<link name='a4'>
		<visual>
			<origin rpy='0 0 0' xyz='0 0 0'/>
			<geometry>
				<cylinder length='0.7' radius='0.43'/>
			</geometry>
			<material name='grey'/>
		</visual>
	</link>
	<joint name='fix_a4_to_l3' type='fixed'>
		<parent link='l3'/>
		<child link='a4'/>
		<axis xyz='0 0 1'/>
		<origin rpy='0 0 0' xyz='0 0 0'/>
	</joint>
	<link name='l4'>
		<visual>
			<origin rpy='0 0 0' xyz='0.0 0.0 0.0'/>
			<geometry>
				<cylinder length='0.0' radius='0.3'/>
			</geometry>
			<material name='white'/>
		</visual>
	</link>
	<joint name='move_l4_from_a4' type='fixed'>
		<parent link='a4'/>
		<child link='l4'/>
		<axis xyz='0 0 1'/>
		<origin rpy='0 0 0' xyz='0 0 0'/>
	</joint>
	<joint name='attachment_joint' type='fixed'>
		<parent link='l4'/>
		<child link='base'/>
		<axis xyz='0 0 1'/>
		<origin rpy='-1.5707963267948966 0 0' xyz='0 0 0.3'/>
	</joint>
  <link name="base">
  <inertial>
    <mass value="1"/>
    <inertia ixx="100" ixy="0" ixz="0" iyy="100" iyz="0" izz="100" />
    <origin/>
  </inertial>
    <visual>
      <geometry>
        <cylinder length='0.15' radius='0.43'/>
      </geometry>
      <origin rpy="1.57 0 0" xyz="0 -0.13 0"/>
      <material name="white">
        <color rgba="1 1 1 1"/>
      </material>
    </visual>
  <collision>
      <origin rpy="1.57 0 0" xyz="0 -0.1 0"/>
    <geometry>
         <cylinder length='0.15' radius='0.43'/>
    </geometry>
    <contact_coefficients mu="0" kp="1000.0" kd="1.0"/>
  </collision>
  </link>

  <link name="left_fingertip">
  <inertial>
    <mass value="1"/>
    <inertia ixx="100" ixy="0" ixz="0" iyy="100" iyz="0" izz="100" />
    <origin/>
  </inertial>
    <visual>
      <geometry>
          <mesh filename="attachments/gripper/finger.stl" scale="3.7 3.7 3.7"/>
      </geometry>
      <origin rpy="1.57 1.57 0" xyz="0.02 0.23 0"/>
      <material name="finger">
        <color rgba="1 1 1 1"/>
      </material>
    </visual>
  <collision>
      <origin rpy="0 0 0" xyz="0 0 0"/>
    <geometry>
        <box size="0.1 .4 .1"/>
    </geometry>
    <contact_coefficients mu="0" kp="1000.0" kd="1.0"/>
  </collision>
  </link>

  <joint name="base_to_left_fingertip" type="prismatic">
    <axis xyz="1 0 0"/>
    <limit effort="1.0" lower="0" upper="0.3" velocity="0.5"/>
    <parent link="base"/>
    <child link="left_fingertip"/>
    <origin xyz="-0.35 -0.4 0.0"/>
  </joint>

  <link name="right_fingertip">
  <inertial>
    <mass value="1"/>
    <inertia ixx="100" ixy="0" ixz="0" iyy="100" iyz="0" izz="100" />
    <origin/>
  </inertial>
    <visual>
       <geometry>
          <mesh filename="attachments/gripper/finger.stl" scale="3.7 3.7 3.7"/>
      </geometry>
      <origin rpy="1.57 -1.57 0" xyz="-0.02 0.23 0"/>
      <material name="finger">
        <color rgba="1 1 1 1"/>
      </material>
    </visual>
  <collision>
     <origin rpy="0 0 0" xyz="0 0 0"/>
    <geometry>
        <box size="0.1 .4 .1"/>
    </geometry>
    <contact_coefficients mu="0" kp="1000.0" kd="1.0"/>
  </collision>
  </link>

  <joint name="base_to_right_fingertip" type="prismatic">
    <axis xyz="1 0 0"/>
    <limit effort="1.0" lower="-0.3" upper="0.0" velocity="0.5"/>
    <parent link="base"/>
    <child link="right_fingertip"/>
    <origin xyz="0.35 -0.4 -0.0"/>
  </joint>
</robot>
