<robot name="gripper">
  <link name="base">
  <inertial>
    <mass value="1"/>
    <inertia ixx="100" ixy="0" ixz="0" iyy="100" iyz="0" izz="100" />
    <origin/>
  </inertial>
    <visual>
      <geometry>
        <cylinder length='0.15' radius='0.43'/>
      </geometry>
      <origin rpy="1.57 0 0" xyz="0 -0.13 0"/>
      <material name="white">
        <color rgba="1 1 1 1"/>
      </material>
    </visual>
  <collision>
      <origin rpy="1.57 0 0" xyz="0 -0.1 0"/>
    <geometry>
         <cylinder length='0.15' radius='0.43'/>
    </geometry>
    <contact_coefficients mu="0" kp="1000.0" kd="1.0"/>
  </collision>
  </link>

  <link name="left_fingertip">
  <inertial>
    <mass value="1"/>
    <inertia ixx="100" ixy="0" ixz="0" iyy="100" iyz="0" izz="100" />
    <origin/>
  </inertial>
    <visual>
      <geometry>
          <mesh filename="attachments/gripper/finger.stl" scale="3.7 3.7 3.7"/>
      </geometry>
      <origin rpy="1.57 1.57 0" xyz="0.02 0.23 0"/>
      <material name="finger">
        <color rgba="1 1 1 1"/>
      </material>
    </visual>
  <collision>
      <origin rpy="0 0 0" xyz="0 0 0"/>
    <geometry>
        <box size="0.1 .4 .1"/>
    </geometry>
    <contact_coefficients mu="0" kp="1000.0" kd="1.0"/>
  </collision>
  </link>

  <joint name="base_to_left_fingertip" type="prismatic">
    <axis xyz="1 0 0"/>
    <limit effort="1.0" lower="0" upper="0.3" velocity="0.5"/>
    <parent link="base"/>
    <child link="left_fingertip"/>
    <origin xyz="-0.35 -0.4 0.0"/>
  </joint>

  <link name="right_fingertip">
  <inertial>
    <mass value="1"/>
    <inertia ixx="100" ixy="0" ixz="0" iyy="100" iyz="0" izz="100" />
    <origin/>
  </inertial>
    <visual>
       <geometry>
          <mesh filename="attachments/gripper/finger.stl" scale="3.7 3.7 3.7"/>
      </geometry>
      <origin rpy="1.57 -1.57 0" xyz="-0.02 0.23 0"/>
      <material name="finger">
        <color rgba="1 1 1 1"/>
      </material>
    </visual>
  <collision>
     <origin rpy="0 0 0" xyz="0 0 0"/>
    <geometry>
        <box size="0.1 .4 .1"/>
    </geometry>
    <contact_coefficients mu="0" kp="1000.0" kd="1.0"/>
  </collision>
  </link>

  <joint name="base_to_right_fingertip" type="prismatic">
    <axis xyz="1 0 0"/>
    <limit effort="1.0" lower="-0.3" upper="0.0" velocity="0.5"/>
    <parent link="base"/>
    <child link="right_fingertip"/>
    <origin xyz="0.35 -0.4 -0.0"/>
  </joint>
</robot>