<!-- DH Parameters and constraints
      Name     theta         d         a     alpha    effort     lower     upper  velocity    visual
  revolute       0.0       2.0       3.0       0.0        10   -3.1416    3.1416       2.6         1
  revolute       0.0       0.0       3.0   -1.5708        10   -2.0944    2.0944       2.6         1
-->
<robot name='robot'>
	<material name='grey'>
		<color rgba='0.6 0.6 0.6 1'/>
	</material>
	<material name='white'>
		<color rgba='1 1 1 1'/>
	</material>
	<link name='a0'>
		<visual>
			<origin rpy='0 0 0' xyz='0 0 0'/>
			<geometry>
				<cylinder length='0.7' radius='0.43'/>
			</geometry>
			<material name='grey'/>
		</visual>
	</link>
	<link name='l0'>
		<visual>
			<origin rpy='-0.0 0.982793723247329 0.0' xyz='1.5 0.0 1.0'/>
			<geometry>
				<cylinder length='3.605551275463989' radius='0.3'/>
			</geometry>
			<material name='white'/>
		</visual>
	</link>
	<joint name='move_l0_from_a0' type='revolute'>
		<parent link='a0'/>
		<child link='l0'/>
		<axis xyz='0 0 1'/>
		<origin rpy='0 0 0' xyz='0 0 0'/>
		<limit effort='10' lower='-3.141592653589793' upper='3.141592653589793' velocity='2.6'/>
	</joint>
	<link name='a1'>
		<visual>
			<origin rpy='0 0 0' xyz='3.00000000000000 0 2.00000000000000'/>
			<geometry>
				<cylinder length='0.7' radius='0.43'/>
			</geometry>
			<material name='grey'/>
		</visual>
	</link>
	<joint name='fix_a1_to_l0' type='fixed'>
		<parent link='l0'/>
		<child link='a1'/>
		<axis xyz='0 0 1'/>
		<origin rpy='0 0 0' xyz='0 0 0'/>
	</joint>
	<link name='l1'>
		<visual>
			<origin rpy='-0.0 1.5707963267948966 0.0' xyz='1.5 0.0 0.0'/>
			<geometry>
				<cylinder length='3.0' radius='0.3'/>
			</geometry>
			<material name='white'/>
		</visual>
	</link>
	<joint name='move_l1_from_a1' type='revolute'>
		<parent link='a1'/>
		<child link='l1'/>
		<axis xyz='0 0 1'/>
		<origin rpy='0 0 0' xyz='3.00000000000000 0 2.00000000000000'/>
		<limit effort='10' lower='-2.0943951023931953' upper='2.0943951023931953' velocity='2.6'/>
	</joint>
	<link name='a2'>
		<visual>
			<origin rpy='-1.57079632679490 0 0' xyz='3.00000000000000 0 0'/>
			<geometry>
				<cylinder length='0.7' radius='0.43'/>
			</geometry>
			<material name='grey'/>
		</visual>
	</link>
	<joint name='fix_a2_to_l1' type='fixed'>
		<parent link='l1'/>
		<child link='a2'/>
		<axis xyz='0 0 1'/>
		<origin rpy='0 0 0' xyz='0 0 0'/>
	</joint>
	<link name='l2'>
		<visual>
			<origin rpy='0 0 0' xyz='0.0 0.0 0.0'/>
			<geometry>
				<cylinder length='0.0' radius='0.3'/>
			</geometry>
			<material name='white'/>
		</visual>
	</link>
	<joint name='move_l2_from_a2' type='fixed'>
		<parent link='a2'/>
		<child link='l2'/>
		<axis xyz='0 0 1'/>
		<origin rpy='-1.57079632679490 0 0' xyz='3.00000000000000 0 0'/>
	</joint>
</robot>
