<!-- DH Parameters 
'r', 1, 2, 0
'r', 1, 2.0, 1.5707963267948966
'p', 0, 3, 0
'f', 2, 0, 2, 0
'r', 0, 2, 0
-->
<robot name='robot'>
	<material name='blue'>
		<color rgba='0.6 0.6 0.6 1'/>
	</material>
	<material name='red'>
		<color rgba='1 1 1 1'/>
	</material>
	<link name='a0'>
		<visual>
			<origin rpy='-0.0 0.0 -0.0' xyz='0.0 0.0 0.0'/>
			<geometry>
				<cylinder length='0.7' radius='0.4'/>
			</geometry>
			<material name='blue'/>
		</visual>
	</link>
	<link name='l0'>
		<visual>
			<origin rpy='-0.0 1.1071487177940904 0.0' xyz='1.0 0.0 0.5'/>
			<geometry>
				<cylinder length='2.23606797749979' radius='0.3'/>
			</geometry>
			<material name='red'/>
		</visual>
	</link>
	<joint name='move_l0_from_a0' type='revolute'>
		<parent link='a0'/>
		<child link='l0'/>
		<axis xyz='0.0 0.0 1.0'/>
		<origin rpy='0 0 0' xyz='0.0 0.0 0.0'/>
		<limit effort='12' lower='-2.9671' upper='2.9671' velocity='2.6100'/>
	</joint>
	<link name='a1'>
		<visual>
			<origin rpy='-0.0 0.0 -0.0' xyz='2.0 0.0 1.0'/>
			<geometry>
				<cylinder length='0.7' radius='0.4'/>
			</geometry>
			<material name='blue'/>
		</visual>
	</link>
	<joint name='fix_a1_to_l0' type='fixed'>
		<parent link='l0'/>
		<child link='a1'/>
		<origin rpy='0 0 0' xyz='0 0 0'/>
	</joint>
	<link name='l1'>
		<visual>
			<origin rpy='-0.0 1.1071487177940904 0.0' xyz='1.0 0.0 0.5'/>
			<geometry>
				<cylinder length='2.23606797749979' radius='0.3'/>
			</geometry>
			<material name='red'/>
		</visual>
	</link>
	<joint name='move_l1_from_a1' type='revolute'>
		<parent link='a1'/>
		<child link='l1'/>
		<axis xyz='0.0 0.0 1.0'/>
		<origin rpy='0 0 0' xyz='2.0 0.0 1.0'/>
		<limit effort='12' lower='-2.9671' upper='2.9671' velocity='2.6100'/>
	</joint>
	<link name='a2'>
		<visual>
			<origin rpy='1.5707963267948966 0.0 -0.0' xyz='2.0 0.0 1.0'/>
			<geometry>
				<cylinder length='0.7' radius='0.4'/>
			</geometry>
			<material name='blue'/>
		</visual>
	</link>
	<joint name='fix_a2_to_l1' type='fixed'>
		<parent link='l1'/>
		<child link='a2'/>
		<origin rpy='0 0 0' xyz='0 0 0'/>
	</joint>
	<link name='l2'>
		<visual>
			<origin rpy='-0.0 1.5707963267948966 0.0' xyz='1.5 0.0 0.0'/>
			<geometry>
				<cylinder length='3.0' radius='0.3'/>
			</geometry>
			<material name='red'/>
		</visual>
		<visual>
			<origin rpy='1.5707963267948966 0.0 -0.0' xyz='0 1.70000000000000 -1.04094977927525E-16'/>
			<geometry>
				<cylinder length='4' radius='0.3'/>
			</geometry>
		</visual>
	</link>
	<joint name='move_l2_from_a2' type='prismatic'>
		<parent link='a2'/>
		<child link='l2'/>
		<axis xyz='0.0 -1.0 6.123233995736766e-17'/>
		<origin rpy='0 0 0' xyz='2.0 0.0 1.0'/>
		<limit effort='12' lower='0.4' upper='4' velocity='2.6100'/>
	</joint>
	<link name='a3'>
		<visual>
			<origin rpy='1.5707963267948966 0.0 -0.0' xyz='3.0 0.0 0.0'/>
			<geometry>
				<cylinder length='0.7' radius='0.4'/>
			</geometry>
			<material name='blue'/>
		</visual>
	</link>
	<joint name='fix_a3_to_l2' type='fixed'>
		<parent link='l2'/>
		<child link='a3'/>
		<origin rpy='0 0 0' xyz='0 0 0'/>
	</joint>
	<link name='l3'>
		<visual>
			<origin rpy='-0.0 0.7853981633974484 0.0' xyz='1.0 0.0 1.0'/>
			<geometry>
				<cylinder length='2.8284271247461903' radius='0.3'/>
			</geometry>
			<material name='red'/>
		</visual>
	</link>
	<joint name='move_l3_from_a3' type='fixed'>
		<parent link='a3'/>
		<child link='l3'/>
		<axis xyz='0.0 -1.0 6.123233995736766e-17'/>
		<origin rpy='0 0 0' xyz='3.0 0.0 0.0'/>
		<limit effort='12' lower='-2.9671' upper='2.9671' velocity='2.6100'/>
	</joint>
	<link name='a4'>
		<visual>
			<origin rpy='1.5707963267948966 0.0 -0.0' xyz='2.0 0.0 2.0'/>
			<geometry>
				<cylinder length='0.7' radius='0.4'/>
			</geometry>
			<material name='blue'/>
		</visual>
	</link>
	<joint name='fix_a4_to_l3' type='fixed'>
		<parent link='l3'/>
		<child link='a4'/>
		<origin rpy='0 0 0' xyz='0 0 0'/>
	</joint>
	<link name='l4'>
		<visual>
			<origin rpy='-0.0 1.5707963267948966 0.0' xyz='1.0 0.0 0.0'/>
			<geometry>
				<cylinder length='2.0' radius='0.3'/>
			</geometry>
			<material name='red'/>
		</visual>
	</link>
	<joint name='move_l4_from_a4' type='revolute'>
		<parent link='a4'/>
		<child link='l4'/>
		<axis xyz='0.0 -1.0 6.123233995736766e-17'/>
		<origin rpy='0 0 0' xyz='2.0 0.0 2.0'/>
		<limit effort='12' lower='-2.9671' upper='2.9671' velocity='2.6100'/>
	</joint>
</robot>
