<robot name="panda"> 

  <link name="link0">
    <visual>
	<origin rpy="0 0 0" xyz="0 0 0"/>
	<geometry>
	  <mesh filename="mesh/L0.stl" scale="0.8 0.8 0.91"/>
	</geometry>
	<material name="white"/>
      </visual>
      <collision>
	<origin rpy="0 0 0" xyz="0 0 0"/>
	<geometry>
	  <mesh filename="mesh/L0.stl" scale="0.8 0.8 0.91"/>
	</geometry>
      </collision>
    </link>

    <joint name="joint1" type="revolute">
      <parent link="link0"/>
      <child link="link1"/>
      <origin xyz="0 0 0.295" rpy="0 0 0"/>
      <axis xyz="0 0 1"/>
      <limit upper="3.665" lower="-3.665" effort="10" velocity="5.024" />
    </joint>

    <link name="link1">
      <visual>
	<origin rpy="0 0 0" xyz="0 0 -0.005"/>
	<geometry>
	  <mesh filename="mesh/L1.stl" scale="0.715 0.715 0.815"/>
	</geometry>
	<material name="white"/>
      </visual>
      <collision>
	<origin rpy="0 0 0" xyz="0 0 -0.005"/>
	<geometry>
	  <mesh filename="mesh/L1.stl" scale="0.715 0.715 0.815"/>
	</geometry>
      </collision>
    </link>

    <joint name="joint2" type="revolute">
      <parent link="link1"/>
      <child link="link2"/>
      <origin xyz="0 0 0" rpy="0 0 0"/>
      <axis xyz="0 1 0"/>
      <limit upper="1.221" lower="-1.7453" effort="10" velocity="5.599666666666667" />
    </joint>

    <link name="link2">
      <visual>
	<origin rpy="0 0 0" xyz="0 0 0"/>
	<geometry>
	  <mesh filename="mesh/L2.stl" scale="0.725 0.670 0.760"/>
	</geometry>
	<material name="white"/>
      </visual>
      <collision>
	<origin rpy="0 0 0" xyz="0 0 0"/>
	<geometry>
	  <mesh filename="mesh/L2.stl" scale="0.725 0.670 0.760"/>
	</geometry>
      </collision>
    </link>

    <joint name="joint3" type="revolute">
      <parent link="link2"/>
      <child link="link3"/>
      <origin xyz="0 0 0.230" rpy="0 0 0"/>
      <axis xyz="0 1 0"/>
      <limit upper="2.268" lower="0.00" effort="10" velocity="6.28" />
    </joint>

    <link name="link3">
      <visual>
	<origin rpy="0 0 0" xyz="-0.002 0 0"/>
	<geometry>
	  <mesh filename="mesh/L3.stl" scale="0.75 0.75 0.75"/>
	</geometry>
	<material name="white"/>
      </visual>
      <collision>
	<origin rpy="0 0 0" xyz="-0.002 0 0"/>
	<geometry>
	  <mesh filename="mesh/L3.stl" scale="0.75 0.75 0.75"/>
	</geometry>
      </collision>
    </link>

    <joint name="joint4" type="revolute">
      <parent link="link3"/>
      <child link="link4"/>
      <origin xyz="-0.05 0 0" rpy="0 0 0"/>
      <axis xyz="0 0 1"/>
      <limit upper="3.141" lower="-3.141" effort="10" velocity="5.8787777777777785" />
    </joint>

    <link name="link4">
      <visual>
	<origin rpy="0 0 0" xyz="0 0 0.265"/>
	<geometry>
	  <mesh filename="mesh/L4.stl" scale="0.7 0.7 0.8"/>
	</geometry>
	<material name="white"/>
      </visual>
      <collision>
	<origin rpy="0 0 0" xyz="0 0 0.265"/>
	<geometry>
	  <mesh filename="mesh/L4.stl" scale="0.7 0.7 0.8"/>
	</geometry>
      </collision>
    </link>

    <joint name="joint5" type="revolute">
      <parent link="link4"/>
      <child link="link5"/>
      <origin xyz="0 0 0.270" rpy="0 0 0"/>
      <axis xyz="0 1 0"/>
      <limit upper="1.745" lower="-1.745" effort="10" velocity="7.85" />
    </joint>

    <link name="link5">
      <visual>
	<origin rpy="0 0 0" xyz="0 0 0"/>
	<geometry>
	  <mesh filename="mesh/L5.stl" scale="0.7 0.7 0.7"/>
	</geometry>
	<material name="white"/>
      </visual>
      <collision>
	<origin rpy="0 0 0" xyz="0 0 0"/>
	<geometry>
	  <mesh filename="mesh/L5.stl" scale="0.7 0.7 0.7"/>
	</geometry>
      </collision>
    </link>

    <joint name="joint6" type="revolute">
      <parent link="link5"/>
      <child link="link6"/>
      <origin xyz="0 0 0.07" rpy="0 0 0"/>
      <axis xyz="0 0 1"/>
      <limit upper="3.490" lower="-3.490" effort="10" velocity="12.56" />
    </joint>

    <link name="link6">
      <visual>
	<origin rpy="0 0 0" xyz="0 0 0"/>
	<geometry>
	  <mesh filename="mesh/L6.stl" scale="0.7 0.7 0.7"/>
	</geometry>
	<material name="white"/>
      </visual>
      <collision>
	<origin rpy="0 0 0" xyz="0 0 0"/>
	<geometry>
	  <mesh filename="mesh/L6.stl" scale="0.7 0.7 0.7"/>
	</geometry>
      </collision>
    </link>
</robot>
